Workbook

Sheet 0. HUB
B2: CLAN CERVECERO × WALMART / PAIZ — HUB DE DATOS
B3: Corte: 24 de agosto de 2026 · venta hasta semana 202629 (15–21 ago) · inventario tiendas 23/08 · bodega Clan EN VIVO (Odoo API) · montos sin IVA
B4: 🧪 ¿Está todo al 100? → 9. DATA CHECK (qué falta y quién lo trae)
B5: EL PULSO
B6: Venta semana: Q 10,906 | E6: Instock de PISO: 29.1% | H6: Instock de SISTEMA: 92.5% | K6: Recuperable / semana: Q 21,611
B7: +5.6% vs anterior | E7: ↑ desde 26.4% · meta 60% | H7: la brecha sigue siendo bodega | K7: 281 combos con stock sin venta
B9: Stock en tiendas: 9,434 u | E9: Pipeline entrante: 0 u | H9: Acciones vencidas o críticas: 5 | K9: Días para vigencia 02/09: 9
B10: Q 272k a costo · −264 u vs 16/08 | E10: ⚠ nada en tránsito ni pedido | H10: ver hoja 1 | K10: 7 ítems no modulados
B12: 🎯 LA TESIS — por qué todo esto: la evidencia por pilar y los KPIs que la validan (clic)
B13: ÍNDICE — clic para ir
B14: 🔴 ACCIÓN
C15: 1. ACCIONES URGENTES | F15: Mesa de pendientes con semáforo, dueño y fecha límite. Empezá aquí.
C16: 2. BITÁCORA | F16: Qué pasó día a día y los hitos que vienen (25/08 → 31/10).
B18: 📈 DESEMPEÑO
C19: 3. KPI SEMANAL | F19: La serie que se alimenta cada semana: venta, instock, fantasmas, pipeline.
C20: Antes vs Después | F20: Semana 202628 vs 202629 por ítem y la lectura honesta del uplift.
C21: 4. SELL-OUT | F21: POS por ítem, por tienda y curva diaria. Regla: surtir jueves.
C22: 5. SELL-THROUGH | F22: Rotación vs inventario: ST% semanal y cobertura por ítem, con semáforo.
C23: 6. SELL-IN PIPELINE | F23: OCs, tránsito (hoy: CERO ⚠), llegadas futuras y pedidos propuestos.
C24: HISTÓRICO 112 SEM | F24: Serie completa desde el ingreso (jul-2024), temporadas 2024 vs 2025 y benchmark.
B25: 📦 INVENTARIO Y PEDIDO
C26: MAX SHELF (VNDR9) | F26: Capacidad de góndola por ítem — la respuesta de Cristian. Trooper 4.1x.
C27: Modelo Pedido | F27: Pedido A (modulados, ejecutable) y B (condicionado). Supuestos editables.
C28: Prepedido Oktoberfest | F28: Reactivación LATA + prepedido 1,000 u + 4-way. Barrilito 5 L descartado 24/08 (sin stock).
C29: Liquidación | F29: 8 inactivos: 1,170 u restantes, por tienda. Sapporo Gold sin ruta.
C30: Vencimientos | F30: Los 7 no modulados: vigencia 02/09 y física 2027-28.
C31: Inventario Clan (Odoo) | F31: NUEVO: bodega en vivo vía API — respaldo del prepedido y hallazgos de facturación.
B32: 🏪 CAMPO
C33: 8. MERCADERISTAS | F33: Estado del proyecto: equipo, cobertura 17/40, calidad del dato.
C34: Campo v2 (17 tiendas) | F34: Hallazgos por tienda 14–24 ago: Mega 6 BORRADO, Pinula vencido, Roosevelt reempaques.
C35: Verificación Campo | F35: Línea base del 14/08 (VN 2% · Pradera 109%).
C36: Prioridad Tiendas | F36: Ruta por olas según Q recuperables.
C37: Plantilla Mercaderistas | F37: Formato estándar de captura con lista de códigos.
B39: 📚 REFERENCIA
C40: 7. CATÁLOGO | F40: Fuente única de los 21 ítems: clase, vigencia, capacidad, logística, notas.
C41: Resumen | F41: Diagnóstico original (corte 16/08) y supuestos del modelo.
C42: Detalle 443 combos | F42: La data cruda combo por combo con filtros.
B44: CÓMO SE ACTUALIZA: cada lunes bajar el "Formato Nuevo Semanal" de Retail Link → columna nueva en KPI SEMANAL → refrescar Antes vs Después y SELL-THROUGH. El campo entra por la Plantilla Mercaderistas. Colores de pestaña: rojo = acción · verde = desempeño · dorado = inventario/pedido · naranja = campo · gris = referencia.

Sheet TESIS
A1: ◀ HUB
B2: LA TESIS — POR QUÉ ESTAMOS HACIENDO TODO ESTO
B3: "Perdimos el control de la operación y con él la venta. Con mercaderistas + gestión + monitoreo, Walmart/Paiz repunta y vende como nunca." — Este hub existe para PROBARLA con datos y trasladarla a los actores.
B5: PILAR 1 · LA CAÍDA FUE DE EJECUCIÓN, NO DE DEMANDA — PROBADO ✔
B6: Afirmación | C6: Evidencia | D6: Dónde verla
B7: La venta cayó a la mitad con el mismo catálogo y las mismas tiendas | C7: 2024: Q 20,486/sem → 2026: Q 10,550/sem (−48%) | D7: HISTÓRICO 112 SEM
B8: El sistema cree que hay producto; el piso no lo tiene | C8: Instock sistema 90-92% vs instock de piso 26.4% (W628) | D8: 3. KPI SEMANAL
B9: El producto existe pero está varado en bodegas de tienda | C9: 295 combos "fantasma": 6,512 u ≈ Q 200k sin exhibir | D9: 4. SELL-OUT
B10: Cuando el producto SÍ está, vende (experimento natural) | C10: Sapporo Black: código viejo agotado vs código nuevo 62 u con CERO venta en las mismas 4 tiendas | D10: Detalle 443 combos
B11: La temporada se ejecutó bien una vez y rota la siguiente | C11: sep-dic 2024: Q 410,613 (+56 a +68%) vs 2025: Q 132,259 (todas negativas) → Q 278k sin capturar | D11: HISTÓRICO 112 SEM
B13: PILAR 2 · LA RED DE MERCADERISTAS + GESTIÓN YA GENERA VALOR — EVIDENCIA TEMPRANA ◐
B14: Afirmación | C14: Evidencia | D14: Dónde verla
B15: La red opera y ve lo que nadie más ve | C15: 17-22 tiendas con evidencia foto; BORRADO en Mega 6 (12/18 SKU), vencido en Pinula, 135 u en reempaques Roosevelt, exclusión de planograma en Américas | D15: Campo v2 (17 tiendas)
B16: Donde se colocó, la venta respondió | C16: Utatlán +56%/día tras colocación; Américas +160% (y era la #1 de la marca); mix premium: Sapporo Silver +133%, Black +85% en W629 | D16: Antes vs Después
B17: El instock de piso empezó a moverse | C17: 26.4% → 29.1% (+2.7 pp) en una semana de trabajo | D17: 3. KPI SEMANAL
B18: Lectura honesta: aún NO hay efecto de red atribuible | C18: La venta total subió +5.6% igual en tiendas con y sin acción; la colocación fue el viernes (1 día de la semana). La prueba limpia es el corte del 05/09 con 2 semanas plenas | D18: Antes vs Después
B20: PILAR 3 · EL REPUNTE ES ALCANZABLE Y MEDIBLE — EN MEDICIÓN ▶
B21: Afirmación | C21: Evidencia | D21: Dónde verla
B22: El techo no es una proyección: es historia propia | C22: Q 20.5k/sem ya se vendió en 2024 con la misma red de tiendas | D22: HISTÓRICO 112 SEM
B23: Las palancas estructurales están identificadas y en gestión | C23: Capacidad de los 7 no modulados (ID 90884), planograma, OCs, reactivaciones Oktoberfest, BORRADO | D23: 1. ACCIONES URGENTES
B24: La bodega respalda el plan (con 1 excepción) | C24: 142,949 u disponibles; lata Oktoberfest 3,705 u (3.7× el prepedido). El barrilito se DESCARTÓ el mismo día (16 u, sin compra en camino): la visibilidad de bodega evitó comprometer lo que no se podía entregar — eso también es control | D24: Inventario Clan (Odoo)
B25: La temporada es la ventana de demostración | C25: Oktoberfest arranca 12/09: lata vendió 2,688 u el ciclo pasado entrando TARDE (dic); este año entramos a tiempo | D25: Prepedido Oktoberfest
B27: KPIs QUE VALIDAN (O REFUTAN) LA TESIS — el marcador del partido
B28: KPI | C28: Base (antes) | D28: Hoy | E28: Meta que valida la tesis | F28: Corte
B29: Instock de piso (combos que venden) | C29: 26.4% (W628) | D29: 29.1% | E29: ≥ 45% al 30/09 · ≥ 60% tiendas Ola 1 | F29: 05/09 y cada lunes
B30: Venta semanal sell-out | C30: Q 10,325 (W628) | D30: Q 10,906 | E30: ≥ Q 15k en oct · ≥ Q 20k nov-dic | F30: cada lunes
B31: Combos fantasma (stock sin venta) | C31: 295 (W628) | D31: 281 | E31: < 100 al 30/09 | F31: cada lunes
B32: Temporada sep-dic (venta total) | C32: Q 132,259 (2025) | D32: — | E32: ≥ Q 300k (2024 hizo Q 410k) | F32: 31/12
B33: Uplift tiendas con acción vs sin acción | C33: sin medición | D33: +56%/día Utatlán (1 caso) | E33: uplift positivo y sostenido en Ola 1 | F33: corte 05/09
B34: Pipeline de reposición entrante | C34: 0 u (23/08) | D34: 0 u ⚠ | E34: flujo continuo ≥ venta semanal | F34: cada lunes
B36: CÓMO SE TRASLADA A LOS ACTORES — de datos a decisiones
B37: Cuándo | C37: Movimiento | D37: Estado
B38: HOY lun 24 | C38: Correo a Max + Cristian (CC Carlos) con PDF de seguimiento: resultados, hallazgos y 6 solicitudes concretas | D38: Borrador listo — lo enviás vos
B39: Jue 27 | C39: Reunión presencial: este hub + deck + muestras físicas + troqueles. El PDF funciona como acta | D39: Deck 15 láminas listo
B40: Vie 05/09 | C40: Corte de uplift con 2 semanas plenas de ejecución (bajar semana 202630 el sáb 29 o lun 31) | D40: La prueba limpia de la tesis
B41: 12/09 | C41: Arranque Oktoberfest en góndola (si la reactivación sale esta semana) | D41: La ventana de demostración
B42: Cada lunes | C42: Refresco del hub (Retail Link + Odoo API) y semáforo de KPIs a los actores | D42: Rutina que sostiene el control
B44: Registro honesto: lo PROBADO está probado con datos verificables; lo TEMPRANO tiene 1 semana de evidencia; la tesis completa se valida (o se ajusta) con los cortes del 05/09 y la temporada.

Sheet 9. DATA CHECK
A1: ◀ HUB | B1: DATA CHECK — ¿está todo al 100?
B2: Corte 24/08/2026 · 18:30. Veredicto: base OPERATIVA completa y cuadrada; de las 9 piezas de MEDICIÓN ya cerraron 3 (histórico, sell-in y AHORA conexión Odoo en vivo). Quedan 6, dos dependen de Walmart.
A4: A · LO QUE ESTÁ COMPLETO Y VALIDADO
A5: Fuente | B5: Cobertura | C5: Validación
A6: Sell-out Retail Link sem 202628 y 202629 | B6: 2 semanas completas, diario, 40 tiendas | C6: Cuadre triple: reporte semanal vs diario vs curva Lun-Dom = Q10,906.1 exacto en los tres
A7: Snapshot de inventario 16/08 y 23/08 | B7: 443 y 429 combos | C7: Consistente entre reportes; caída de universo explicada (ver C)
A8: Capacidad de góndola (VNDR9 de Cristian, 18/08) | B8: 39 de 40 tiendas, 13 ítems | C8: Cruza perfecto con campo: shelf 0 ↔ BORRADO/NO TRT/liquidación
A9: Maestro artículo-tienda-válida D96 (23/08) | B9: 6 modulados × 34-40 tiendas | C9: Consistente con VNDR9 (tipo 33 = M)
A10: Campo mercaderistas v1+v2 | B10: 17 de 40 tiendas, 67 mensajes | C10: Códigos normalizados; totales recalculados del detalle (verificacion_automatica)
A11: Catálogo comercial (21 ítems + clases) | B11: Completo | C11: Correlación clase↔vencimiento sin excepciones
A12: Artes 4-pack Trooper y Hobgoblin | B12: Troqueles finales | C12: Listos para alta
A13: Torre de Control W29 | B13: Semanal propio funcionando | C13: Coincide en dirección; denominador distinto documentado (ver C)
A14: Odoo (API en vivo, 24/08) | B14: Sell-in 2026 + bodega completa | C14: Cuadre mensual exacto vs export 19/08 (dif. explicadas); share Walmart 17.7% consistente con estimación previa (~18%)
A15: B · LAS 9 PIEZAS QUE FALTAN — en orden de impacto
A16: # | B16: Pieza faltante | C16: Para qué sirve | D16: Quién / cómo se consigue | E16: Cuándo
A17: 1 | B17: Venta semana 202630 (22–28 ago) | C17: La medición REAL del uplift: 2 semanas completas post-colocación | D17: Vos: bajar Formato Nuevo Semanal en Retail Link | E17: sábado 29 o lunes 31
A18: 2 | B18: ✔ CERRADO 24/08 — 112 semanas consolidadas (backfill del repo + FNS master). Ver hoja HISTÓRICO 112 SEM | C18: Estacionalidad, tendencia y validar el prepedido Oktoberfest con base, no con 2 puntos | D18: Vos: mismo reporte de Retail Link con rango "Últimas 13 semanas" (una sola bajada) | E18: esta semana
A19: 3 | B19: ✔ CERRADO 24/08 — CONEXIÓN ODOO EN VIVO (API xmlrpc): sell-in 2026 Q 485,911 (17.7% de Clan), bodega 139 SKUs / 142,949 u, hallazgos de facturación. Historia 2024-25 desde legacy (ya en HISTÓRICO). Ver hoja Inventario Clan (Odoo). | C19: Cerrar el círculo sell-in vs sell-out vs inventario; hoy el hub solo tiene el lado Walmart | D19: Vos: export de Odoo (o conectar la Torre — su pendiente A20) | E19: esta semana
A20: 4 | B20: Estado real de las OC 105573289/290 | C20: El pipeline en CERO sugiere que se cancelaron; si es así, no hay reposición en camino | D20: Preguntar a Cristian (Odoo no registra la referencia de OC del cliente: no rastreable de nuestro lado) | E20: 25/08
A21: 5 | B21: Scorecard de fill rate / OTIF del proveedor | C21: Es el número con el que Walmart los mide a USTEDES; sin él, el sell-in está ciego | D21: Pedir a Cristian el reporte de fill rate del proveedor 258977960 | E21: esta semana
A22: 6 | B22: Chat WhatsApp exportado del teléfono | C22: Cierra la brecha 18/08 14:01 → 20/08 19:02 (posibles reportes perdidos) | D22: Vos: WhatsApp > chat > exportar (sin medios basta) | E22: cuando puedas
A23: 7 | B23: SKU/lote/cantidad del vencido en Pinula + reporte Chiquimula | C23: Cerrar el riesgo #3 y completar cobertura Nor-Oriente | D23: Zetino (Pinula) y Sucely Guerra vía Gladys Díaz | E23: 48 h
A24: 8 | B24: Maestro de estatus de TODOS los ítems del proveedor (no solo válidos) | C24: Dimensionar el alcance real del BORRADO: hoy solo lo vemos donde el campo miró | D24: Pedir a Max el reporte de estatus de artículo por proveedor, o correrlo en Retail Link | E24: esta semana
A25: 9 | B25: Costo real de flete/entrada por caja | C25: Afinar márgenes del hub (hoy: costo Retail Link, que puede no incluir logística) | D25: Vos: dato interno Clan | E25: opcional
A27: C · DECISIONES DE MÉTODO (para no pelearse con los números después)
A28: IVA — el hallazgo que resuelve el "misterio" de precios
A29: El anaquel real (handheld San Lucas) está 12% arriba del "Precio Unitario" de Retail Link en TODOS los ítems no liquidados. Es el IVA: Retail Link reporta SIN IVA. → Todos los Q del hub son sin IVA; el consumidor paga 12% más. Las 3 excepciones con precio menor (St Peter's Q30.2/Q20, Hobgoblin Q20) son las rebajas de liquidación — validadas.
A30: Universo fijo
A31: El Formato Semanal solo trae combos con actividad: el denominador cambió solo de 443 → 429 (salieron 14 combos inactivos ya drenados y 2 quiebres de Helles; entraron 2). DECISIÓN PROPUESTA: medir instock sobre el universo VNDR9 (combinaciones autorizadas) para modulados + catálogo activo para el resto, y dejar el universo "con actividad" solo como referencia. Así el KPI no mejora "gratis" cuando un combo muere.
A32: Tienda 40
A33: WM Quetzaltenango Periférico (1087) NO existe en el VNDR9: cero capacidad definida en todos los ítems. Toda medición de capacidad es sobre 39 tiendas; 1087 necesita decisión de Walmart (¿entra al modular o se saca del universo?).
A34: Momento del snapshot
A35: El inventario es el corte del sábado siguiente a la semana de venta. Sell-through usa OH inicial = snapshot previo. Documentado en cada hoja.
A37: D · CHEQUEOS DE INTEGRIDAD CORRIDOS HOY
A38: Chequeo | B38: Resultado
A39: Cuadre venta 202629 entre 3 reportes independientes (771 semanal / 573 diario / 554 curva) | B39: ✔ Q10,906 exacto en los tres
A40: Suma diaria 202628 vs total semanal | B40: ✔ Q10,325.05 exacto
A41: VNDR9 vs maestro D96 (tipo 33 ↔ MBM=M) | B41: ✔ consistente, 6/6 ítems
A42: Campo vs sistema (BORRADO/NO TRT ↔ shelf 0/OTRO) | B42: ✔ Mega 6, Huehue y Cobán coinciden en las dos fuentes
A43: Códigos de ítem del campo | B43: ✔ 7 errores de digitación normalizados; plantilla con lista desplegable lista
...

Sheet 1. ACCIONES URGENTES
A1: ◀ HUB | B1: ACCIONES URGENTES — mesa de pendientes
B2: Corte 24/08/2026. Ordenado por urgencia. Filtrá con los encabezados. Semáforo: 🔴 vencido / crítico · 🟡 esta semana · 🟢 programado.
A4: Semáforo | B4: # | C4: Acción | D4: Alcance | E4: Dueño sugerido | F4: Estado | G4: Fecha límite | H4: Fuente
A5: 🔴 | B5: 4 | C5: Reescalar exclusión del planograma con dato de venta (+160% esa semana) | D5: Paiz Américas | E5: Diego → Max/SERGIO | F5: Escalado 17/08, SIN RESPUESTA 7 días | G5: VENCIDO | H5: Campo 17/08
A6: 🔴 | B6: 6 | C6: Producto vencido en sala: exigir SKU, lote, foto y retiro | D6: Paiz Pinula | E6: Jelver Miranda GSP | F6: Escalado 24/08 sin detalle | G6: 48 horas | H6: Campo 24/08
A7: 🔴 | B7: 3 | C7: Vigencia + MAX_SHELF de los 7 no modulados (hoy capacidad = 0) | D7: Toda la red | E7: Max Sosa (ID 90884) | F7: Abierto desde 04/06 | G7: 02/09 (9 días) | H7: VNDR9 + Retail Link
A8: 🔴 | B8: 1 | C8: Solicitar reactivación HB Oktoberfestbier LATA con capacidad asignada (barrilito descartado 24/08 por stock) | D8: Catálogo | E8: Diego → Max | F8: Sin solicitar | G8: 25/08 | H8: Reunión 18/08
A9: 🔴 | B9: 2 | C9: Enviar prepedido Oktoberfest a Cristian (1,000 u lata — SOLO lata) | D9: Toda la red | E9: Diego | F9: Borrador listo | G9: 25/08 | H9: Hoja Prepedido
A10: 🟡 | B10: 7 | C10: Alta 4-packs Trooper y Hobgoblin con render 3D (Hofbräu falta arte) | D10: Temporada | E10: Diego → Max | F10: Troqueles finales listos | G10: ~05/09 (modular Halloween) | H10: PDFs troquel
A11: 🟡 | B11: 5 | C11: Confirmar si BORRADO de 12 SKU es decisión de cadena y en cuántas tiendas aplica | D11: Paiz Mega 6 → cadena | E11: Max Sosa | F11: Nuevo 21/08 | G11: Esta semana | H11: Campo + VNDR9
A12: 🟡 | B12: 9 | C12: Recuperar 28 u St Peter's Suffolk del área de merma | D12: WM Naranjo | E12: Mercaderista Daya | F12: Abierto | G12: Esta semana | H12: Campo 18/08
A13: 🟡 | B13: 10 | C13: Reconteos pendientes: WM Naranjo (desde 18/08) y Villa Nueva (brecha 204 u) | D13: 2 tiendas | E13: Supervisión GSP | F13: Abierto | G13: Esta semana | H13: Campo v2
A14: 🟡 | B14: 12 | C14: Reporte faltante Paiz Chiquimula (Jr Sucely Guerra) | D14: 1 tienda | E14: Gladys Díaz | F14: Sin reporte | G14: Esta semana | H14: Campo v2
A15: 🟡 | B15: 8 | C15: Rotar lote Trooper dic-2026 (66 u documentadas) vía 4-way / cara Trooper | D15: 5 tiendas | E15: Diego + GSP | F15: Documentado | G15: Septiembre | H15: VISUAL + campo
A16: 🟢 | B16: 11 | C16: Exportar chat WhatsApp del teléfono (brecha 18-20/08) | D16: Datos | E16: Diego | F16: Identificada | G16: Cuando se pueda | H16: Reporte v2
... A18: 🟢 | B18: 14 | C18: Torre de Control: cargar MAX_SHELF completo (Libro9), llave Resend, firma v1 | D18: Interno | E18: Diego | F18: 6/9 criterios sin reserva | G18: 25/08 revisar criterio 4 | H18: CANAL MODERNO

Sheet 2. BITÁCORA
A1: ◀ HUB | B1: BITÁCORA — qué cambió y qué viene
B2: Cronología del proyecto + hitos futuros. Los hitos en ámbar aún dependen de una acción abierta.
A4: Fecha | B4: Tipo | C4: Evento | D4: Efecto / por qué importa
A5: 12/08 | B5: NP | C5: Diego envía formato de nota prioritaria a Max/Carlos/Cristian | D5: Arranca el proyecto de colocación
A6: 13/08 | B6: Sell-in | C6: Cristian emite OC 105573289 y 105573290 (cancelación 18/08), condicionadas a aplicar NP | D6: Pipeline de reposición condicionado
A7: 14/08 | B7: Campo | C7: Primeros conteos: VN 10/257 físico (2%), Pradera 155/142 (109%); grupo WhatsApp activo (24 miembros) | D7: Línea base del proyecto
A8: 17/08 08:58 | B8: NP | C8: Carlos publica NP I000106341_v001 (WM y Super, 24 líneas) | D8: Instrucción formal a tiendas
A9: 17/08 09:19 | B9: Riesgo | C9: Paiz Américas: planograma nuevo SIN la marca | D9: Riesgo estructural #1; sigue sin respuesta
A10: 17/08 | B10: Campo | C10: San Lucas reporta con precios y modulación; pide NP para Helles y Belhaven | D10: Primer reporte "completo"
A11: 18/08 11:00 | B11: Reunión | C11: PROPUESTAS TEMPORADA con Max y Cristian (Teams) | D11: Se presentan diagnóstico, pedidos A/B y 5 SKUs de temporada
A12: 18/08 11:48 | B12: Sistema | C12: Cristian responde con VNDR9 "MAX SHELF": modulados con capacidad; tipo 03 = 0 | D12: Confirmación estructural de la hipótesis
A13: 18/08 | B13: Campo | C13: Utatlán coloca 3 SKU fuera de plano → venta +56%/día | D13: Primera evidencia de uplift por ejecución
A14: 20/08 | B14: Campo | C14: Roosevelt: 615 u cuadradas 100% pero 135 u en reempaques; San Cristóbal casi cuadrado | D14: La modulación del ~05/08 dejó producto empacado
A15: 21/08 | B15: Riesgo | C15: Mega 6: 12 de 18 SKU BORRADO en maestro de tienda; Pacific Center: FOTD vence 31/12/26 liquidado | D15: Baja de surtido parametrizada + lote corto
... A19: 24/08 | B19: Análisis | C19: Sem 202629: red +5.6%; Sapporo Silver +133%, Black +85%; instock piso 26.4%→29.1% | D19: El uplift arrancó por los premium
A20: — PRÓXIMOS HITOS —
A21: 25/08 | B21: HITO | C21: Enviar reactivación Oktoberfest + prepedido a Cristian | D21: Sin esto no hay temporada Oktoberfest
A22: ~29/08 | B22: HITO | C22: Cierra ventana modular Oktoberfest (góndola 12/09) | D22: 4-pack Hofbräu + reactivaciones deben estar en trámite
A23: 02/09 | B23: HITO | C23: Vencen los 7 ítems no modulados (vigencia de catálogo) | D23: Si no se extiende: medio surtido activo se apaga
A24: ~05/09 | B24: HITO | C24: Cierra ventana modular Halloween + corte de medición (2 semanas completas de colocación) | D24: Alta de 4-packs Trooper/Hobgoblin; medición seria del uplift
A25: 12/09 | B25: HITO | C25: Producto Oktoberfest en góndola + llegada Sapporo Black 20 u a Roosevelt | D25: Arranque de temporada
A26: 19/09–04/10 | B26: HITO | C26: Oktoberfest (191ª edición, Múnich) | D26: Ventana de venta
A27: 01/10 | B27: HITO | C27: 4-pack Hobgoblin Halloween en góndola; 4-way rota cara a Halloween | D27: Segunda ola de temporada
A28: 31/10 | B28: HITO | C28: Halloween | D28: Pico de venta esperado

Sheet 3. KPI SEMANAL
A1: ◀ HUB | B1: KPI SEMANAL — la serie que se alimenta cada semana
B2: Semana Walmart corre sábado→viernes. Columna nueva cada semana con el reporte "Formato Nuevo Semanal". El corte de inventario es el snapshot de la semana siguiente.
A4: KPI | B4: Sem 202628 (8–14 ago) | C4: Sem 202629 (15–21 ago) | D4: Δ | E4: Sem 202630 (22–28) | F4: Meta
A5: Sell-out (Q) | B5: 10325.05 | C5: 10906 | D5: =C5-B5 -> 580.95 | E5: pendiente corte 30/08 | F5: —
A6: Sell-out (unidades) | B6: 323 | C6: 333 | D6: =C6-B6 -> 10 | F6: —
A7: Instock de PISO (combos con venta) | B7: 0.264 | C7: 0.291 | D7: =C7-B7 -> 0.027 | F7: 60%
A8: Instock de SISTEMA (combos con stock) | B8: 0.901 | C8: 0.925 | D8: =C8-B8 -> 0.024 | F8: 95%
A9: Combos fantasma (stock sin venta) | B9: 295 | C9: 281 | D9: =C9-B9 -> -14 | F9: <150
A10: Unidades inmovilizadas en fantasmas | B10: 6512 | C10: 5751 | D10: =C10-B10 -> -761 | F10: <3,000
A11: Venta perdida recuperable (Q/sem) | B11: 21855 | C11: 21611 | D11: =C11-B11 -> -244 | F11: <10,000
A12: Stock total red (u, corte siguiente) | B12: 9698 | C12: 9434 | D12: =C12-B12 -> -264 | F12: —
A13: Stock inactivo a liquidar (u) | B13: 1252 | C13: 1170 | D13: =C13-B13 -> -82 | F13: 0
A14: Ticket implícito (Q/u) | B14: 31.96 | C14: 32.75 | D14: =C14-B14 -> 0.79 | F14: —
A15: Pipeline entrante (tránsito+pedido, u) | B15: 508 | C15: 0 | D15: =C15-B15 -> -508 | F15: >0 ⚠
A16: ⚠ Pipeline entrante en CERO: al corte del 23/08 no hay ni tránsito ni pedido de tienda en ninguna combinación. Nada viene en camino — si las OC del 13/08 se cancelaron, la reposición está apagada. Verificar con Cristian.

Sheet Antes vs Después
A1: ANTES VS DESPUÉS — semana 202628 (8–14 ago) vs 202629 (15–21 ago)
A2: NP publicada 17/08; colocación arrancó 18/08 → la semana 202629 solo trae 4 días de efecto parcial. Fuente: Retail Link, solicitudes 113137399 y 113345771.
A3: ◀ HUB
A4: RED COMPLETA
A5: Métrica | B5: Sem 202628 | C5: Sem 202629 | D5: Δ | E5: Δ %
A6: Venta (Q) | B6: 10325.05 | C6: 10906 | D6: =C6-B6 -> 580.95 | E6: =IFERROR(C6/B6-1,"") -> 0.056266071
A7: Venta (unidades) | B7: 323 | C7: 333 | D7: =C7-B7 -> 10 | E7: =IFERROR(C7/B7-1,"") -> 0.030959752
A8: Combos con venta (de 443) | B8: 117 | C8: 125 | D8: =C8-B8 -> 8 | E8: =IFERROR(C8/B8-1,"") -> 0.068376068
A9: Ticket implícito (Q/u) | B9: 31.96 | C9: 32.75 | D9: =C9-B9 -> 0.79 | E9: =IFERROR(C9/B9-1,"") -> 0.024718398
A11: POR ÍTEM (venta Q) — el uplift está en Sapporo
A12: Ítem | B12: Descripción | C12: Clase | D12: 202628 | E12: 202629 | F12: Δ Q | G12: Δ %
A13: 75214930 | B13: SAPPORO SILVER 650ML | C13: MODULADO | D13: 1108.98 | E13: 2587.62 | F13: =E13-D13 -> 1478.64 | G13: =IFERROR(E13/D13-1,"") -> 1.3333333
A14: 75437621 | B14: TROOPERORIGINAL LATA | C14: MODULADO | D14: 2134.58 | E14: 1767.76 | F14: =E14-D14 -> -366.82 | G14: =IFERROR(E14/D14-1,"") -> -0.17184645
A15: 75437610 | B15: SAPPORO BLACK 650 ML | C15: MODULADO | D15: 862.42 | E15: 1594.04 | F15: =E15-D15 -> 731.62 | G15: =IFERROR(E15/D15-1,"") -> 0.84833376
A16: 75437616 | B16: HB DUNKEL 500 ML | C16: MODULADO | D16: 538.46 | E16: 1073.22 | F16: =E16-D16 -> 534.76 | G16: =IFERROR(E16/D16-1,"") -> 0.99312855
A17: 75437623 | B17: TROOPER FOTD 500 ML | C17: MODULADO | D17: 1795.39 | E17: 933.17 | F17: =E17-D17 -> -862.22 | G17: =IFERROR(E17/D17-1,"") -> -0.48024106
A18: 75437614 | B18: HB ORIGINAL 500 ML | C18: MODULADO | D18: 745.16 | E18: 873.92 | F18: =E18-D18 -> 128.76 | G18: =IFERROR(E18/D18-1,"") -> 0.1727951
A19: 75437615 | B19: HB HELLES LAGER LATA | C19: NO MODULADO | D19: 707.72 | E19: 602.03 | F19: =E19-D19 -> -105.69 | G19: =IFERROR(E19/D19-1,"") -> -0.14933872
A20: 75437613 | B20: NC OLD RASPUTIN LATA | C20: NO MODULADO | D20: 683.52 | E20: 398.72 | F20: =E20-D20 -> -284.8 | G20: =IFERROR(E20/D20-1,"") -> -0.41666667
A21: 75214932 | B21: SAPPORO GOLD 650 ML | C21: INACTIVO | D21: 527.7 | E21: 364.3 | F21: =E21-D21 -> -163.4 | G21: =IFERROR(E21/D21-1,"") -> -0.30964563
A22: 75437612 | B22: NC SCRIMSHAW LATA | C22: NO MODULADO | D22: 140.71 | E22: 284.8 | F22: =E22-D22 -> 144.09 | G22: =IFERROR(E22/D22-1,"") -> 1.024021
A23: 75253329 | B23: HB MUNCHNER 500 ML | C23: INACTIVO | D23: 120.52 | E23: 161.55 | F23: =E23-D23 -> 41.03 | G23: =IFERROR(E23/D23-1,"") -> 0.34044142
A24: 75253328 | B24: STPET SUFFOLK 500 | C24: INACTIVO | D24: 375.88 | E24: 89.28 | F24: =E24-D24 -> -286.6 | G24: =IFERROR(E24/D24-1,"") -> -0.76247739
... A33: 75244433 | B33: HOBGOBLIN GOLD 500 | C33: INACTIVO | D33: 0 | E33: 0 | F33: =E33-D33 -> 0 | G33: =IFERROR(E33/D33-1,"")
B34: TOTAL | D34: =SUM(D13:D33) -> 10325.05 | E34: =SUM(E13:E33) -> 10906.04 | F34: =SUM(F13:F33) -> 580.99
A36: LECTURA HONESTA
A37: La red creció +5.6% en Q — y el crecimiento fue idéntico en tiendas con acción documentada (+5.6%) y sin ella (+5.6%): todavía NO hay señal atribuible a nivel red. Con 4 días de colocación parcial es lo esperable.
A38: Donde SÍ hay señal es en el mix: Sapporo Silver +133% (Q1,109→Q2,588) y Sapporo Black +85% (Q862→Q1,594). Los dos modulados premium suman +Q2,211/semana. Trooper Original cayó Q-367: el mix rotó hacia ticket alto.
A39: Casos puntuales: Paiz Utatlán +56%/día tras colocar el 18/08 (el mercaderista puso 3 SKU fuera de plano en espacio adicional). Paiz Américas +160% (Q502→Q1,308) la semana del incidente de planograma.
A40: Por qué no se ve más: WM Roosevelt tiene 135 u inmovilizadas en reempaques, Villa Nueva sigue con 204 u de brecha física, Huehuetenango estuvo bloqueada por inventario general, y los 7 no modulados siguen sin capacidad de góndola (ver hoja MAX SHELF).

Sheet 4. SELL-OUT
A1: ◀ HUB | B1: SELL-OUT (POS Walmart/Paiz) — lo que el consumidor pagó en caja
B2: Por ítem y por tienda, semanas 202628 vs 202629. La vista por día está al final: la venta es de fin de semana (72% cae V-S-D).
A4: POR ÍTEM
A5: Ítem | B5: Descripción | C5: Clase | D5: u 628 | E5: Q 628 | F5: u 629 | G5: Q 629 | H5: Δ Q | I5: Δ %
A6: 75214930 | B6: SAPPORO SILVER 650ML | C6: MODULADO | D6: 18 | E6: 1108.98 | F6: 42 | G6: 2587.62 | H6: =G6-E6 -> 1478.64 | I6: =IFERROR(G6/E6-1,"") -> 1.3333333
A7: 75437621 | B7: TROOPERORIGINAL LATA | C7: MODULADO | D7: 91 | E7: 2134.58 | F7: 76 | G7: 1767.76 | H7: =G7-E7 -> -366.82 | I7: =IFERROR(G7/E7-1,"") -> -0.17184645
A8: 75437610 | B8: SAPPORO BLACK 650 ML | C8: MODULADO | D8: 13 | E8: 862.42 | F8: 26 | G8: 1594.04 | H8: =G8-E8 -> 731.62 | I8: =IFERROR(G8/E8-1,"") -> 0.84833376
A9: 75437616 | B9: HB DUNKEL 500 ML | C9: MODULADO | D9: 21 | E9: 538.46 | F9: 45 | G9: 1073.22 | H9: =G9-E9 -> 534.76 | I9: =IFERROR(G9/E9-1,"") -> 0.99312855
A10: 75437623 | B10: TROOPER FOTD 500 ML | C10: MODULADO | D10: 47 | E10: 1795.39 | F10: 23 | G10: 933.17 | H10: =G10-E10 -> -862.22 | I10: =IFERROR(G10/E10-1,"") -> -0.48024106
A11: 75437614 | B11: HB ORIGINAL 500 ML | C11: MODULADO | D11: 26 | E11: 745.16 | F11: 32 | G11: 873.92 | H11: =G11-E11 -> 128.76 | I11: =IFERROR(G11/E11-1,"") -> 0.1727951
A12: 75437615 | B12: HB HELLES LAGER LATA | C12: NO MODULADO | D12: 44 | E12: 707.72 | F12: 35 | G12: 602.03 | H12: =G12-E12 -> -105.69 | I12: =IFERROR(G12/E12-1,"") -> -0.14933872
A13: 75437613 | B13: NC OLD RASPUTIN LATA | C13: NO MODULADO | D13: 12 | E13: 683.52 | F13: 7 | G13: 398.72 | H13: =G13-E13 -> -284.8 | I13: =IFERROR(G13/E13-1,"") -> -0.41666667
A14: 75214932 | B14: SAPPORO GOLD 650 ML | C14: INACTIVO | D14: 11 | E14: 527.7 | F14: 8 | G14: 364.3 | H14: =G14-E14 -> -163.4 | I14: =IFERROR(G14/E14-1,"") -> -0.30964563
A15: 75437612 | B15: NC SCRIMSHAW LATA | C15: NO MODULADO | D15: 3 | E15: 140.71 | F15: 5 | G15: 284.8 | H15: =G15-E15 -> 144.09 | I15: =IFERROR(G15/E15-1,"") -> 1.024021
A16: 75253329 | B16: HB MUNCHNER 500 ML | C16: INACTIVO | D16: 4 | E16: 120.52 | F16: 9 | G16: 161.55 | H16: =G16-E16 -> 41.03 | I16: =IFERROR(G16/E16-1,"") -> 0.34044142
A17: 75253328 | B17: STPET SUFFOLK 500 | C17: INACTIVO | D17: 16 | E17: 375.88 | F17: 4 | G17: 89.28 | H17: =G17-E17 -> -286.6 | I17: =IFERROR(G17/E17-1,"") -> -0.76247739
... A26: 75244433 | B26: HOBGOBLIN GOLD 500 | C26: INACTIVO | D26: 0 | E26: 0 | F26: 0 | G26: 0 | H26: =G26-E26 -> 0 | I26: =IFERROR(G26/E26-1,"")
B27: TOTAL | D27: =SUM(D6:D26) -> 323 | E27: =SUM(E6:E26) -> 10325.05 | F27: =SUM(F6:F26) -> 333 | G27: =SUM(G6:G26) -> 10906.04 | H27: =SUM(H6:H26) -> 580.99
A29: POR TIENDA (Q)
A30: Tienda # | B30: Nombre | C30: Q 628 | D30: Q 629 | E30: Δ Q | F30: Δ % | G30: Acción documentada
A31: 22 | B31: PAIZ LAS AMERICAS | C31: 502.44 | D31: 1308.44 | E31: =D31-C31 -> 806 | F31: =IFERROR(D31/C31-1,"") -> 1.6041716 | G31: Américas planograma 17
A32: 457 | B32: PAIZ ASUNCION | C32: 466.7 | D32: 865.46 | E32: =D32-C32 -> 398.76 | F32: =IFERROR(D32/C32-1,"") -> 0.85442468
A33: 108 | B33: PAIZ PRADERA | C33: 670.72 | D33: 717.22 | E33: =D33-C33 -> 46.5 | F33: =IFERROR(D33/C33-1,"") -> 0.069328483 | G33: Pradera conteo 14
A34: 491 | B34: PAIZ COBAN | C34: 801.82 | D34: 630.86 | E34: =D34-C34 -> -170.96 | F34: =IFERROR(D34/C34-1,"") -> -0.21321494 | G34: Cobán 21-22/08 colocó
A35: 47 | B35: PAIZ MONTBLANC | C35: 108.75 | D35: 479.11 | E35: =D35-C35 -> 370.36 | F35: =IFERROR(D35/C35-1,"") -> 3.4056092
A36: 4037 | B36: WM DEL NORTE | C36: 521.35 | D36: 444.99 | E36: =D36-C36 -> -76.36 | F36: =IFERROR(D36/C36-1,"") -> -0.14646591
A37: 727 | B37: PAIZ COLONIA VISTA HERMOS | C37: 385.65 | D37: 427.05 | E37: =D37-C37 -> 41.4 | F37: =IFERROR(D37/C37-1,"") -> 0.10735123
A38: 46 | B38: PAIZ MEGA 6 | C38: 53.56 | D38: 376.85 | E38: =D38-C38 -> 323.29 | F38: =IFERROR(D38/C38-1,"") -> 6.0360344
A39: 4433 | B39: PAIZ SANTA CATARINA PINUL | C39: 83.69 | D39: 339.18 | E39: =D39-C39 -> 255.49 | F39: =IFERROR(D39/C39-1,"") -> 3.052814
A40: 23 | B40: PAIZ NOVICENTRO ZONA 11 | C40: 871.34 | D40: 337.86 | E40: =D40-C40 -> -533.48 | F40: =IFERROR(D40/C40-1,"") -> -0.61225239
A41: 121 | B41: WM ROOSEVELT | C41: 174.86 | D41: 335.72 | E41: =D41-C41 -> 160.86 | F41: =IFERROR(D41/C41-1,"") -> 0.91993595 | G41: Roosevelt conteo 20
A42: 1054 | B42: WALMART SAN CRISTóBAL | C42: 44.64 | D42: 331.98 | E42: =D42-C42 -> 287.34 | F42: =IFERROR(D42/C42-1,"") -> 6.436828
A43: 4414 | B43: WM ATANASIO TZUL | C43: 385.19 | D43: 325.45 | E43: =D43-C43 -> -59.74 | F43: =IFERROR(D43/C43-1,"") -> -0.15509229
A44: 33 | B44: PAIZ AGUILAR BATRES | C44: 106.42 | D44: 319.37 | E44: =D44-C44 -> 212.95 | F44: =IFERROR(D44/C44-1,"") -> 2.0010336
A45: 459 | B45: WM BOSQ SAN NICOLAS | C45: 178.56 | D45: 288.88 | E45: =D45-C45 -> 110.32 | F45: =IFERROR(D45/C45-1,"") -> 0.61783154
A46: 180 | B46: PAIZ HUEHUETENANGO | C46: 218.3 | D46: 252.04 | E46: =D46-C46 -> 33.74 | F46: =IFERROR(D46/C46-1,"") -> 0.15455795
A47: 34 | B47: PAIZ UTATLAN | C47: 276.77 | D47: 235.46 | E47: =D47-C47 -> -41.31 | F47: =IFERROR(D47/C47-1,"") -> -0.14925751 | G47: Utatlán 18/08 colocó
A48: 169 | B48: PAIZ SAN CRISTOBAL | C48: 645.58 | D48: 230.44 | E48: =D48-C48 -> -415.14 | F48: =IFERROR(D48/C48-1,"") -> -0.64304966
A49: 4087 | B49: PAIZ EL NARANJO | C49: 381.25 | D49: 229.82 | E49: =D49-C49 -> -151.43 | F49: =IFERROR(D49/C49-1,"") -> -0.39719344 | G49: P.Naranjo visib 18
A50: 419 | B50: PAIZ MAZATENANGO | C50: 52.45 | D50: 218.92 | E50: =D50-C50 -> 166.47 | F50: =IFERROR(D50/C50-1,"") -> 3.1738799
...

Sheet 5. SELL-THROUGH
A1: ◀ HUB | B1: SELL-THROUGH — qué tan rápido rota lo que ya está en tienda
B2: ST% = unidades vendidas en la semana ÷ inventario al inicio. Cobertura = semanas para vaciar el stock actual al ritmo actual. Un portafolio de importación sano ronda 8–15% semanal; hoy la red está en 3.4%.
A4: Ítem | B4: Descripción | C4: Clase | D4: OH inicio (16/08) | E4: Venta u 629 | F4: ST semanal % | G4: OH fin (23/08) | H4: Cobertura (sem) | I4: Semáforo
A5: 75214930 | B5: SAPPORO SILVER 650ML | C5: MODULADO | D5: 754 | E5: 42 | F5: =IFERROR(E5/D5,0) -> 0.055702918 | G5: 784 | H5: =IFERROR(G5/E5,"∞") -> 18.666667 | I5: LENTO
A6: 75437621 | B6: TROOPERORIGINAL LATA | C6: MODULADO | D6: 2675 | E6: 76 | F6: =IFERROR(E6/D6,0) -> 0.028411215 | G6: 2617 | H6: =IFERROR(G6/E6,"∞") -> 34.434211 | I6: CRÍTICO
A7: 75437610 | B7: SAPPORO BLACK 650 ML | C7: MODULADO | D7: 721 | E7: 26 | F7: =IFERROR(E7/D7,0) -> 0.036061026 | G7: 708 | H7: =IFERROR(G7/E7,"∞") -> 27.230769 | I7: LENTO
A8: 75437616 | B8: HB DUNKEL 500 ML | C8: MODULADO | D8: 1186 | E8: 45 | F8: =IFERROR(E8/D8,0) -> 0.037942664 | G8: 1174 | H8: =IFERROR(G8/E8,"∞") -> 26.088889 | I8: LENTO
A9: 75437623 | B9: TROOPER FOTD 500 ML | C9: MODULADO | D9: 703 | E9: 23 | F9: =IFERROR(E9/D9,0) -> 0.032716927 | G9: 631 | H9: =IFERROR(G9/E9,"∞") -> 27.434783 | I9: LENTO
A10: 75437614 | B10: HB ORIGINAL 500 ML | C10: MODULADO | D10: 872 | E10: 32 | F10: =IFERROR(E10/D10,0) -> 0.036697248 | G10: 823 | H10: =IFERROR(G10/E10,"∞") -> 25.71875 | I10: LENTO
A11: 75437615 | B11: HB HELLES LAGER LATA | C11: NO MODULADO | D11: 328 | E11: 35 | F11: =IFERROR(E11/D11,0) -> 0.10670732 | G11: 275 | H11: =IFERROR(G11/E11,"∞") -> 7.8571429 | I11: SANO
A12: 75437613 | B12: NC OLD RASPUTIN LATA | C12: NO MODULADO | D12: 379 | E12: 7 | F12: =IFERROR(E12/D12,0) -> 0.018469657 | G12: 353 | H12: =IFERROR(G12/E12,"∞") -> 50.428571 | I12: CRÍTICO
A13: 75214932 | B13: SAPPORO GOLD 650 ML | C13: INACTIVO | D13: 339 | E13: 8 | F13: =IFERROR(E13/D13,0) -> 0.02359882 | G13: 286 | H13: =IFERROR(G13/E13,"∞") -> 35.75 | I13: CRÍTICO
A14: 75437612 | B14: NC SCRIMSHAW LATA | C14: NO MODULADO | D14: 491 | E14: 5 | F14: =IFERROR(E14/D14,0) -> 0.010183299 | G14: 508 | H14: =IFERROR(G14/E14,"∞") -> 101.6 | I14: CRÍTICO
A15: 75253329 | B15: HB MUNCHNER 500 ML | C15: INACTIVO | D15: 300 | E15: 9 | F15: =IFERROR(E15/D15,0) -> 0.03 | G15: 287 | H15: =IFERROR(G15/E15,"∞") -> 31.888889 | I15: LENTO
A16: 75253328 | B16: STPET SUFFOLK 500 | C16: INACTIVO | D16: 514 | E16: 4 | F16: =IFERROR(E16/D16,0) -> 0.0077821012 | G16: 504 | H16: =IFERROR(G16/E16,"∞") -> 126 | I16: CRÍTICO
... A25: 75244436 | B25: HOBGOBLIN STOUT 500 | C25: INACTIVO | D25: 2 | E25: 0 | F25: =IFERROR(E25/D25,0) -> 0 | G25: 2 | H25: =IFERROR(G25/E25,"∞") -> ∞ | I25: CRÍTICO
A27: El único ST sano de la red es HB Helles Lager (10.7%) — no modulado, sin capacidad asignada y con vigencia al 10/11. El ítem que mejor rota es el que el sistema está por apagar.
A28: Trooper Original: 2.8% de ST con 34 semanas de cobertura. Combinado con la saturación 4.1x (hoja MAX SHELF): no pedir, exhibir y drenar.
A29: St Peter's Stout vendió 12 u a Q0.22 promedio — es la liquidación a Q0.25 detectada por el campo en Puerta Parada, no venta real.

Sheet 6. SELL-IN PIPELINE
A1: ◀ HUB | B1: SELL-IN — lo que Clan factura a la cadena y lo que viene en camino
B2: El sell-in granular vive en Odoo/Torre de Control; aquí va el pipeline visible en Retail Link + OCs conocidas + pedidos propuestos.
A4: ÓRDENES DE COMPRA CONOCIDAS
A5: OC / PO Host | B5: Número | C5: Emitida | D5: Condición | E5: Estado al 24/08
A6: 2401060119 | B6: 105573289 | C6: 13/08 | D6: Cubrir ítems tipo 03 con outs — condicionada a aplicar NP | E6: VERIFICAR: cancelación era 18/08; pipeline actual = 0 sugiere que no viajó
A7: 2401060120 | B7: 105573290 | C7: 13/08 | D7: Ídem | E7: VERIFICAR: ídem
A9: PIPELINE EN RETAIL LINK (tránsito + pedido de tienda)
A10: Corte | B10: En tránsito (u) | C10: En pedido de tienda (u) | D10: Total | E10: Lectura
A11: 16/08 (sem 202629) | B11: 148 | C11: 360 | D11: =B11+C11 -> 508 | E11: Reposición viajando hacia tiendas con bodega llena
A12: 23/08 (sem 202630) | B12: 0 | C12: 0 | D12: =B12+C12 -> 0 | E12: ⚠ CERO en toda la red: la reposición está apagada. Si las OC no aplicaron, nada llega antes de la temporada
A14: LLEGADAS FUTURAS CONFIRMADAS (campo)
A15: Fecha | B15: Tienda | C15: Ítem | D15: Unidades
A16: 12/09 | B16: WM Roosevelt | C16: Sapporo Black 650 | D16: 20
A18: SELL-IN PROPUESTO (pendiente de aprobación)
A19: Concepto | B19: Unidades | C19: Valor estimado | D19: Estado
A20: Prepedido HB Oktoberfestbier lata (50 cajas) | B20: 1000 | C20: Q 20,000 a PVP | D20: Borrador de correo listo — enviar 25/08
A21: Prepedido barrilito 5 L — DESCARTADO 24/08 | B21: 0 | C21: — | D21: Descartado: 16 u en bodega y sin compra en camino; se vende solo lata
A22: Pedido A — 6 modulados (modelo) | B22: 3686 | C22: Q 123,398 a costo | D22: Hoja Modelo Pedido — frenar Trooper Original
A23: Pedido B — 7 no modulados (condicionado a vigencia+capacidad) | B23: 2438 | C23: Q 55,354 a costo | D23: Bloqueado por ID 90884
A25: Sell-in de referencia de otras cadenas (Torre de Control, W29): La Torre Q 24,432 (660 u) facturado esa semana. El comparativo completo Odoo↔cadenas queda para cuando exista el dato conciliado (A20 de tu Torre).

Sheet Inventario Clan (Odoo)
A1: ◀ HUB
B2: INVENTARIO CLAN — BODEGA (ODOO, API EN VIVO)
B3: Conexión xmlrpc a clancervecero.odoo.com · corte 24/08/2026 · 139 SKUs con existencia · 142,949 unidades totales · "disponible" = a mano − reservado
B5: A · RESPALDO DE BODEGA PARA EL CATÁLOGO WALMART (13 ítems + temporada)
B6: Ítem WM | C6: Código Odoo | D6: Producto (catálogo) | E6: Clase | F6: Disponible bodega (u) | G6: Venta WM u/sem 629 | H6: Cobertura bodega (sem) | I6: Semáforo | J6: Lectura
B7: 75214930 | C7: CC-SAP-02 | D7: SAPPORO PREMIUM SILVER LATA 650 ML | E7: MODULADO | F7: 1510 | G7: 42 | H7: 36 | I7: 🟢 | J7: La que más creció (+133%): vigilar que bodega acompañe la temporada
B8: 75437610 | C8: CC-SAP-03 | D8: SAPPORO BLACK LATA 650 ML | E8: MODULADO | F8: 1000 | G8: 26 | H8: 38.5 | I8: 🟢
B9: 75437614 | C9: CC-HB-01 | D9: HOFBRAU HB ORIGINAL BOTELLA 500 ML | E9: MODULADO | F9: 9 | G9: 32 | H9: 0.3 | I9: 🔴 | J9: Solo 9 u: si el modulado repone, no hay respaldo → decidir importación
B10: 75437616 | C10: CC-HB-02 | D10: HOFBRAU HB DUNKEL BOTELLA 500 ML | E10: MODULADO | F10: 2912 | G10: 45 | H10: 64.7 | I10: 🟢
B11: 75437621 | C11: CC-TROO-04 | D11: TROOPER ORIGINAL LATA 500 ML | E11: MODULADO | F11: 64 | G11: 76 | H11: 0.8 | I11: 🔴 | J11: 64 u en bodega PERO tiendas 4.1× sobre capacidad: primero drenar tienda
B12: 75437623 | C12: CC-TROOP-03 | D12: TROOPER FEAR OF THE DARK LATA 500 ML | E12: MODULADO | F12: 5901 | G12: 23 | H12: 256.6 | I12: 🟢
B13: 75437612 | C13: CC-NC-15 | D13: NORTH COAST SCRIMSHAW LATA 568 ML | E13: NO MODULADO | F13: 1032 | G13: 5 | H13: 206.4 | I13: 🟢
B14: 75437613 | C14: CC-NC-14 | D14: NORTH COAST OLD RASPUTIN LATA 568 ML | E14: NO MODULADO | F14: 930 | G14: 7 | H14: 132.9 | I14: 🟢
B15: 75437615 | C15: CC-HB-09 | D15: HOFBRAU HELLES LAGER LATA 500 ML | E15: NO MODULADO | F15: 4284 | G15: 35 | H15: 122.4 | I15: 🟢
B16: 75437617 | C16: CC-HB-10 | D16: HOFBRAU SESSION LAGER LATA 500 ML | E16: NO MODULADO | F16: 1516 | G16: 1 | H16: 1516 | I16: 🟢
B17: 75437618 | C17: CC-BEL-01 | D17: BELHAVEN BEST LATA 440 ML | E17: NO MODULADO | F17: 1075 | G17: 3 | H17: 358.3 | I17: 🟢
B18: 75437619 | C18: CC-BEL-02 | D18: BELHAVEN BLACK LATA 440 ML | E18: NO MODULADO | F18: 851 | G18: 2 | H18: 425.5 | I18: 🟢
B19: 75437620 | C19: CC-BEL-03 | D19: BELHAVEN MCCALLUMS LATA 440 ML | E19: NO MODULADO | F19: 2126 | G19: 1 | H19: 2126 | I19: 🟢
B22: B · TEMPORADA E INNOVACIÓN — ¿la bodega respalda lo que estamos pidiendo?
B23: Propuesta | C23: Código(s) | D23: Uso | E23: Disponible (u) | F23: Semáforo | G23: Lectura
B24: HB Oktoberfestbier LATA 500 ml | C24: CC-HB-07 | D24: Reactivación + prepedido 1,000 u | E24: 3,705 | F24: 🟢 | G24: Cubre 3.7× el prepedido; alcanza para todo el ciclo si rota como 2024 (2,688 u)
B25: Barrilito Oktoberfest 5 L | C25: CC-HB-08 | D25: DESCARTADO del prepedido (24/08) | E25: 16 | F25: ✖ | G25: Sin stock (16 u) y sin compra en camino: se vende solo lata. La visibilidad evitó comprometer lo que no podíamos entregar.
B26: 4-pack Trooper (base FOTD lata) | C26: CC-TROOP-03 | D26: Armado de packs | E26: 5,901 | F26: 🟢 | G26: Sobra base para armar packs
B27: 4-pack Hobgoblin (King Ruby + Gold + IPA) | C27: CC-HOB-05/04/01/03 | D27: Armado de packs | E27: 4,772 | F27: 🟢 | G27: 1,903 King + 1,228 Ruby + 1,185 Gold + 456 IPA
B28: 4-pack Hofbräu (Dunkel/Helles/Weisse/Session) | C28: CC-HB-02/09/03/10 | D28: Armado de packs | E28: 10,933 | F28: 🟢 | G28: 2,912 + 4,296 + 2,209 + 1,516
B29: Barril HB Oktoberfestbier 24 L (horeca) | C29: BCC-HB-03 | D29: Fuera de alcance Walmart | E29: 14 | F29: — | G29: Referencia: canal horeca
B32: C · HALLAZGOS DE LA CONEXIÓN EN VIVO (24/08)
B33: Qué | C33: Dato | D33: Y entonces
B34: Sell-in Walmart/Paiz 2026 (posteado) | C34: Q 485,911 · 17,900 u · última factura 03/08 | D34: Es el 17.7% de la venta total Clan 2026 (Q 2,744,032). 2024-25 viven en el legacy (ya integrado en HISTÓRICO).
B35: Factura sin postear | C35: S00863 (04/08, ~Q 7.8k sin IVA) está en borrador | D35: Postearla: agosto está subestimado en contabilidad
B36: Entrega sin facturar | C36: S00912 (12/08, Q 9.3k) entregada y sin factura hace 12 días | D36: Facturarla: flujo y antigüedad de saldo
B37: Refacturación | C37: FEL0789 (Q 31.2k) anulada → FEL0791 posteada mismo día | D37: OK, solo explica el cuadre vs export del 19/08
B38: OCs 105573289/290 | C38: La referencia de OC del cliente NO se registra en las órdenes de Odoo | D38: No se puede rastrear desde Odoo → mantener pregunta a Cristian y empezar a llenar "Referencia de pedido" en cada SO
B39: Lotes y vencimientos | C39: Odoo NO rastrea lotes (0 quants con lote) | D39: Vencimientos siguen viniendo de campo/legacy; activar rastreo por lote sería el cierre definitivo
B40: Compras en tránsito | C40: 0 líneas de compra pendientes de recibir en todo 2026 | D40: Nada en camino registrado: lo que no está en bodega, no existe para la temporada
B43: D · TOP 15 BODEGA GENERAL (contexto del portafolio)
B44: Código | C44: Producto | D44: A mano (u) | E44: Disponible (u)
B45: CC-BM-01 | C45: CAJA BLUE MOON BELGIAN WHITE | D45: 42932 | E45: 42920
B46: CC-LAN-01 | C46: LANDSHARK LAGER | D46: 12863 | E46: 12863
B47: CC-TROOP-03 | C47: CAJA TROOPER FEAR OF THE DARK LATA | D47: 5901 | E47: 5901
...

Sheet HISTÓRICO 112 SEM
A1: ◀ HUB | B1: HISTÓRICO COMPLETO — 112 semanas desde el ingreso (jul-2024 → ago-2026)
B2: Fuentes: backfill Retail Link (202423–202515, parquets del repo CANAL MODERNO) + FNS master (202516–202629). Serie continua, sin huecos. Q sin IVA.
B4: LA FOTO ANUAL
B5: Año | C5: Semanas | D5: Venta total | E5: Promedio semanal | F5: vs 2024
B6: 2024 (desde jul) | C6: 31 | D6: 635057 | E6: 20486
B7: 2025 | C7: 52 | D7: 620912 | E7: 11941 | F7: -42%
B8: 2026 (a ago) | C8: 29 | D8: 306522 | E8: 10570 | F8: -48%
B9: El pico del negocio ya existió: Q20,486/semana sostenido en 2024 con ~35 tiendas. Hoy, con 40 tiendas, la mitad. El "techo" del modelo de pedido no es teoría — es historia propia.
B11: TEMPORADAS — el mismo calendario, dos ejecuciones
B12: Ventana | C12: 2024 (Q/sem) | D12: uplift vs base | E12: 2025 (Q/sem) | F12: uplift vs base | G12: Lectura
B13: Oktoberfest (sep-oct) | C13: 29381 | D13: +63% | E13: 8458 | F13: -31% | G13: Bien ejecutada renta +63%; rota, rinde negativo
B14: Halloween (oct-nov) | C14: 28074 | D14: +56% | E14: 9080 | F14: -26%
B15: Navidad (nov-dic) | C15: 30282 | D15: +68% | E15: 10730 | F15: -13% | G15: La mejor ventana del año
B16: TOTAL sep-dic | D16: Q 410,613 | F16: Q 132,259 | G16: Q 278k dejados sobre la mesa en 2025
B18: Mix de temporada (sep-oct): Sapporo 56–61% de la venta las dos veces — el protagonista. Trooper cayó de 15.9% (2024) a 5.9% (2025).
B20: BENCHMARK OKTOBERFEST — la venta real del ciclo pasado
B21: Ítem | C21: Unidades | D21: Venta | E21: Tiendas | F21: PVP | G21: Timing
B22: HB Oktoberfest LATA (75273066) | C22: 2688 | D22: 49530 | E22: 35 | F22: Q 20.8 | G22: Entró TARDE: vendió dic-24 → mar-25
B23: HB Oktober BARRIL (75273067) | C23: 141 | D23: 30267 | E23: 14 | F23: Q 250 | G23: Ídem; 10 u/tienda promedio
B24: 75437611 (código nuevo, a reactivar) | C24: 5 | D24: 104 | E24: 3 | F24: — | G24: Remanentes feb-mar 2026: el ítem existe y responde
B25: Implicación directa para el prepedido: aun entrando en DICIEMBRE, la lata vendió 2,688 u y el barril facturó Q30k a Q250. El prepedido de 1,000 u + 56 barrilitos con entrada 12/09 es conservador; el potencial de ciclo completo es 2,500–3,000 latas.
B27: SELL-IN CLAN → WALMART (Odoo, "Operadora de Tiendas S.A.", con IVA)
B28: Año | C28: Facturado | D28: Nota
B29: 2024 | C29: 1095150 | D29: año de entrada — el mejor
B30: 2025 | C30: 890931 | D30: -19%
B31: 2026 YTD (jul) | C31: 503312 | D31: fuente: legacy Odoo 29/07
B32: sep-25 → ago-26 | C32: 524932 | D32: parquet Odoo 19/08 · Walmart = 18% de la facturación total de Clan
B34: SERIE SEMANAL COMPLETA (base del gráfico y de cualquier análisis)
B35: Semana | C35: Inicio | D35: Venta Q | E35: Unidades | F35: Combos c/venta
B36: 202423 | C36: 2024-07-01 | D36: 519.67 | E36: 9 | F36: 8
B37: 202424 | C37: 2024-07-06 | D37: 8022.87 | E37: 163 | F37: 98
B38: 202425 | C38: 2024-07-13 | D38: 8759.49 | E38: 171 | F38: 98
B39: 202426 | C39: 2024-07-20 | D39: 6313.85 | E39: 133 | F39: 85
B40: 202427 | C40: 2024-07-27 | D40: 4824.41 | E40: 93 | F40: 72
B41: 202428 | C41: 2024-08-03 | D41: 4411.9 | E41: 88 | F41: 57
B42: 202429 | C42: 2024-08-10 | D42: 11173.01 | E42: 213 | F42: 124
B43: 202430 | C43: 2024-08-17 | D43: 22063.1 | E43: 411 | F43: 203
B44: 202431 | C44: 2024-08-24 | D44: 24601.48 | E44: 513 | F44: 304
B45: 202432 | C45: 2024-08-31 | D45: 27905.6 | E45: 550 | F45: 303
B46: 202433 | C46: 2024-09-07 | D46: 25607.16 | E46: 501 | F46: 311
...

Sheet MAX SHELF (VNDR9)
A1: CAPACIDAD DE GÓNDOLA — respuesta de Cristian, correo 18/08 "MAX SHELF O CAPACIDAD DE GONDOLA"
A2: Formato VNDR9 (Libro9.xlsx). Confirma la hipótesis de la reunión: los 6 modulados (tipo 33) tienen MAX_SHELF asignado; los 7 no modulados (tipo 03, aprov "OTRO") tienen MAX_SHELF = 0 en el 100% de sus filas.
A3: ◀ HUB
A4: Ítem | B4: Descripción | C4: Filas VNDR9 | D4: Capacidad total red (u) | E4: Capacidad prom/tienda | F4: Tiendas con shelf 0 | G4: Existencia red 202630 (u) | H4: Saturación (OH ÷ capacidad) | I4: Lectura
A5: 75214930 | B5: SAPPORO PREMIUM SILVER LATA 650 | C5: 39 | D5: 896 | E5: 23 | F5: 0 | G5: 784 | H5: =G5/D5 -> 0.875 | I5: Sana: cabe todo lo que hay
A6: 75437610 | B6: SAPPORO BLACK LATA 650 | C6: 39 | D6: 752 | E6: 19.3 | F6: 0 | G6: 708 | H6: =G6/D6 -> 0.94148936 | I6: Sana: cabe todo lo que hay
A7: 75437614 | B7: HB ORIGINAL BOTELLA 500 | C7: 39 | D7: 690 | E7: 17.7 | F7: 1 | G7: 823 | H7: =G7/D7 -> 1.1927536 | I7: Leve exceso (1.2x)
A8: 75437616 | B8: HB DUNKEL BOTELLA 500 | C8: 39 | D8: 561 | E8: 14.4 | F8: 1 | G8: 1174 | H8: =G8/D8 -> 2.0926916 | I8: 2.1x: mitad del stock no tiene dónde exhibirse
A9: 75437621 | B9: TROOPER ORIGINAL LATA 500 | C9: 39 | D9: 645 | E9: 16.5 | F9: 2 | G9: 2617 | H9: =G9/D9 -> 4.0573643 | I9: 4.1x: la góndola solo absorbe el 25% del stock. El resto vive en bodega POR DISEÑO
A10: 75437623 | B10: TROOPER FEAR OF THE DARK LATA 500 | C10: 39 | D10: 624 | E10: 16 | F10: 6 | G10: 631 | H10: =G10/D10 -> 1.0112179 | I10: Ajustada 1.0x — ojo: 6 tiendas con shelf 0 (Novicentro, Utatlán, Montblanc, S.Pacífico, Cobán, Liberación)
A12: LOS 7 NO MODULADOS (Helles, Session, Scrimshaw, Old Rasputin, 3 Belhaven): aparecen en VNDR9 con tipo 03, aprovisionamiento "OTRO" y MAX_SHELF = 0 en todas las tiendas. Sin capacidad, la reposición automática no dispara jamás: quiebre estructural, no operativo. Coincide con lo que reportó el campo (Mega 6: estatus BORRADO; San Lucas: "sin modular").
A14: MODULADOS CON HUECOS: Trooper Original con shelf 0 / aprov OTRO en Mega 6 (96 u en tienda, maestro local "NO TRT") y Huehuetenango. Trooper FOTD con shelf 0 en 6 tiendas Paiz. HB Original y Dunkel con aprov OTRO en Cobán — y Cobán reporta esos mismos SKU en liquidación. El VNDR9 y el campo cuentan la misma historia.
A16: TROOPER ORIGINAL, EL CASO DE FONDO: capacidad de red 645 u contra 2,617 en tiendas (4.1x). Aunque los mercaderistas llenen cada frente, 3 de cada 4 latas no tienen dónde exhibirse. Esto no se arregla colocando: se arregla con más frentes (modular de octubre) o frenando compra (ya está en sobre-stock en el modelo de pedido).

Sheet Modelo Pedido
A1: MODELO DE PEDIDO — solo los 13 ítems activos
A2: Los 8 ítems inactivos NO se pueden pedir: van a liquidación (ver hoja Liquidación). Supuestos en Resumen!D8:D11.
A3: Verde = modulado (espacio permanente, sin vencimiento). Ámbar = no modulado (depende de nota prioritaria y tiene vencimiento).
A4: ◀ HUB
A5: Ítem | B5: Descripción de catálogo | C5: Clase | D5: Expira | E5: Tiendas | F5: Stock (u) | G5: Tasa obs. (u/tda/sem) | H5: Demanda/sem (u) | I5: Cobertura (sem) | J5: Demanda horizonte (u) | K5: Stock seg. (u) | L5: Necesidad (u) | M5: SUGERIDO (u) | N5: Costo unit. | O5: SUGERIDO (Q costo) | P5: Perdida/sem (Q) | Q5: Semáforo
A6: 75437623 | B6: TROOPER FEAR OF THE DARK LATA 500 ML | C6: MODULADO | D6: — | E6: 40 | F6: 703 | G6: 2.94 | H6: =E6*G6*Resumen!$D$9 -> 82.32 | I6: =IFERROR(F6/H6,0) -> 8.5398445 | J6: =H6*Resumen!$D$8*(1+Resumen!$D$10) -> 1712.256 | K6: =H6*Resumen!$D$11 -> 164.64 | L6: =J6+K6 -> 1876.896 | M6: =ROUND(MAX(0,L6-F6),0) -> 1174 | N6: 32.85 | O6: =M6*N6 -> 38565.9 | P6: 2755 | Q6: =IF(H6=0,"SIN TASA — no vendió",IF(I6>Resumen!$D$8,"SOBRE-STOCK",IF(I6<4,"REPONER YA","OK"))) -> OK
A7: 75437616 | B7: HOFBRAU HB DUNKEL BOTELLA 500 ML | C7: MODULADO | D7: — | E7: 40 | F7: 1186 | G7: 3 | H7: =E7*G7*Resumen!$D$9 -> 84 | I7: =IFERROR(F7/H7,0) -> 14.119048 | J7: =H7*Resumen!$D$8*(1+Resumen!$D$10) -> 1747.2 | K7: =H7*Resumen!$D$11 -> 168 | L7: =J7+K7 -> 1915.2 | M7: =ROUND(MAX(0,L7-F7),0) -> 729 | N7: 22 | O7: =M7*N7 -> 16038 | P7: 2743 | Q7: =IF(H7=0,"SIN TASA — no vendió",IF(I7>Resumen!$D$8,"SOBRE-STOCK",IF(I7<4,"REPONER YA","OK"))) -> OK
A8: 75214930 | B8: SAPPORO PREMIUM SILVER LATA 650 ML | C8: MODULADO | D8: — | E8: 40 | F8: 754 | G8: 2.25 | H8: =E8*G8*Resumen!$D$9 -> 63 | I8: =IFERROR(F8/H8,0) -> 11.968254 | J8: =H8*Resumen!$D$8*(1+Resumen!$D$10) -> 1310.4 | K8: =H8*Resumen!$D$11 -> 126 | L8: =J8+K8 -> 1436.4 | M8: =ROUND(MAX(0,L8-F8),0) -> 682 | N8: 45.54 | O8: =M8*N8 -> 31058.28 | P8: 3881 | Q8: =IF(H8=0,"SIN TASA — no vendió",IF(I8>Resumen!$D$8,"SOBRE-STOCK",IF(I8<4,"REPONER YA","OK"))) -> OK
A9: 75437614 | B9: HOFBRAU HB ORIGINAL BOTELLA 500 ML | C9: MODULADO | D9: — | E9: 40 | F9: 872 | G9: 2.36 | H9: =E9*G9*Resumen!$D$9 -> 66.08 | I9: =IFERROR(F9/H9,0) -> 13.196126 | J9: =H9*Resumen!$D$8*(1+Resumen!$D$10) -> 1374.464 | K9: =H9*Resumen!$D$11 -> 132.16 | L9: =J9+K9 -> 1506.624 | M9: =ROUND(MAX(0,L9-F9),0) -> 635 | N9: 22 | O9: =M9*N9 -> 13970 | P9: 1823 | Q9: =IF(H9=0,"SIN TASA — no vendió",IF(I9>Resumen!$D$8,"SOBRE-STOCK",IF(I9<4,"REPONER YA","OK"))) -> OK
A10: 75437610 | B10: SAPPORO BLACK LATA 650 ML | C10: MODULADO | D10: — | E10: 40 | F10: 721 | G10: 1.86 | H10: =E10*G10*Resumen!$D$9 -> 52.08 | I10: =IFERROR(F10/H10,0) -> 13.844086 | J10: =H10*Resumen!$D$8*(1+Resumen!$D$10) -> 1083.264 | K10: =H10*Resumen!$D$11 -> 104.16 | L10: =J10+K10 -> 1187.424 | M10: =ROUND(MAX(0,L10-F10),0) -> 466 | N10: 51 | O10: =M10*N10 -> 23766 | P10: 3681 | Q10: =IF(H10=0,"SIN TASA — no vendió",IF(I10>Resumen!$D$8,"SOBRE-STOCK",IF(I10<4,"REPONER YA","OK"))) -> OK
A11: 75437621 | B11: TROOPER ORIGINAL LATA 500 ML | C11: MODULADO | D11: — | E11: 40 | F11: 2675 | G11: 3.79 | H11: =E11*G11*Resumen!$D$9 -> 106.12 | I11: =IFERROR(F11/H11,0) -> 25.207312 | J11: =H11*Resumen!$D$8*(1+Resumen!$D$10) -> 2207.296 | K11: =H11*Resumen!$D$11 -> 212.24 | L11: =J11+K11 -> 2419.536 | M11: =ROUND(MAX(0,L11-F11),0) -> 0 | N11: 18.25 | O11: =M11*N11 -> 0 | P11: 1166 | Q11: =IF(H11=0,"SIN TASA — no vendió",IF(I11>Resumen!$D$8,"SOBRE-STOCK",IF(I11<4,"REPONER YA","OK"))) -> SOBRE-STOCK
A12: 75437615 | B12: HOFBRAU HELLES LAGER LATA 500 ML | C12: NO MODULADO | D12: 10/11/2026 | E12: 29 | F12: 328 | G12: 4.4 | H12: =E12*G12*Resumen!$D$9 -> 89.32 | I12: =IFERROR(F12/H12,0) -> 3.6721899 | J12: =H12*Resumen!$D$8*(1+Resumen!$D$10) -> 1857.856 | K12: =H12*Resumen!$D$11 -> 178.64 | L12: =J12+K12 -> 2036.496 | M12: =ROUND(MAX(0,L12-F12),0) -> 1708 | N12: 16 | O12: =M12*N12 -> 27328 | P12: 1370 | Q12: =IF(H12=0,"SIN TASA — no vendió",IF(I12>Resumen!$D$8,"SOBRE-STOCK",IF(I12<4,"REPONER YA","OK"))) -> REPONER YA
A13: 75437613 | B13: NORTH COAST OLD RASPUTIN LATA 568 ML | C13: NO MODULADO | D13: 02/09/2026 | E13: 25 | F13: 379 | G13: 2.4 | H13: =E13*G13*Resumen!$D$9 -> 42 | I13: =IFERROR(F13/H13,0) -> 9.0238095 | J13: =H13*Resumen!$D$8*(1+Resumen!$D$10) -> 873.6 | K13: =H13*Resumen!$D$11 -> 84 | L13: =J13+K13 -> 957.6 | M13: =ROUND(MAX(0,L13-F13),0) -> 579 | N13: 43.8 | O13: =M13*N13 -> 25360.2 | P13: 2722 | Q13: =IF(H13=0,"SIN TASA — no vendió",IF(I13>Resumen!$D$8,"SOBRE-STOCK",IF(I13<4,"REPONER YA","OK"))) -> OK
A14: 75437619 | B14: BELHAVEN BLACK LATA 440 ML | C14: NO MODULADO | D14: 02/09/2026 | E14: 5 | F14: 49 | G14: 2 | H14: =E14*G14*Resumen!$D$9 -> 7 | I14: =IFERROR(F14/H14,0) -> 7 | J14: =H14*Resumen!$D$8*(1+Resumen!$D$10) -> 145.6 | K14: =H14*Resumen!$D$11 -> 14 | L14: =J14+K14 -> 159.6 | M14: =ROUND(MAX(0,L14-F14),0) -> 111 | N14: 18.25 | O14: =M14*N14 -> 2025.75 | P14: 95 | Q14: =IF(H14=0,"SIN TASA — no vendió",IF(I14>Resumen!$D$8,"SOBRE-STOCK",IF(I14<4,"REPONER YA","OK"))) -> OK
A15: 75437617 | B15: HOFBRAU SESSION LAGER LATA 500 ML | C15: NO MODULADO | D15: 02/09/2026 | E15: 10 | F15: 120 | G15: 1 | H15: =E15*G15*Resumen!$D$9 -> 7 | I15: =IFERROR(F15/H15,0) -> 17.142857 | J15: =H15*Resumen!$D$8*(1+Resumen!$D$10) -> 145.6 | K15: =H15*Resumen!$D$11 -> 14 | L15: =J15+K15 -> 159.6 | M15: =ROUND(MAX(0,L15-F15),0) -> 40 | N15: 16 | O15: =M15*N15 -> 640 | P15: 145 | Q15: =IF(H15=0,"SIN TASA — no vendió",IF(I15>Resumen!$D$8,"SOBRE-STOCK",IF(I15<4,"REPONER YA","OK"))) -> SOBRE-STOCK
A16: 75437612 | B16: NORTH COAST SCRIMSHAW LATA 568 ML | C16: NO MODULADO | D16: 02/09/2026 | E16: 30 | F16: 491 | G16: 1 | H16: =E16*G16*Resumen!$D$9 -> 21 | I16: =IFERROR(F16/H16,0) -> 23.380952 | J16: =H16*Resumen!$D$8*(1+Resumen!$D$10) -> 436.8 | K16: =H16*Resumen!$D$11 -> 42 | L16: =J16+K16 -> 478.8 | M16: =ROUND(MAX(0,L16-F16),0) -> 0 | N16: 43.8 | O16: =M16*N16 -> 0 | P16: 1474 | Q16: =IF(H16=0,"SIN TASA — no vendió",IF(I16>Resumen!$D$8,"SOBRE-STOCK",IF(I16<4,"REPONER YA","OK"))) -> SOBRE-STOCK
A17: 75437618 | B17: BELHAVEN BEST LATA 440 ML | C17: NO MODULADO | D17: 02/09/2026 | E17: 6 | F17: 76 | G17: 0 | H17: =E17*G17*Resumen!$D$9 -> 0 | I17: =IFERROR(F17/H17,0) -> 0 | J17: =H17*Resumen!$D$8*(1+Resumen!$D$10) -> 0 | K17: =H17*Resumen!$D$11 -> 0 | L17: =J17+K17 -> 0 | M17: =ROUND(MAX(0,L17-F17),0) -> 0 | N17: 18.25 | O17: =M17*N17 -> 0 | P17: 0 | Q17: =IF(H17=0,"SIN TASA — no vendió",IF(I17>Resumen!$D$8,"SOBRE-STOCK",IF(I17<4,"REPONER YA","OK"))) -> SIN TASA — no vendió
A18: 75437620 | B18: BELHAVEN MCCALLUMS LATA 440 ML | C18: NO MODULADO | D18: 02/09/2026 | E18: 8 | F18: 92 | G18: 0 | H18: =E18*G18*Resumen!$D$9 -> 0 | I18: =IFERROR(F18/H18,0) -> 0 | J18: =H18*Resumen!$D$8*(1+Resumen!$D$10) -> 0 | K18: =H18*Resumen!$D$11 -> 0 | L18: =J18+K18 -> 0 | M18: =ROUND(MAX(0,L18-F18),0) -> 0 | N18: 18.25 | O18: =M18*N18 -> 0 | P18: 0 | Q18: =IF(H18=0,"SIN TASA — no vendió",IF(I18>Resumen!$D$8,"SOBRE-STOCK",IF(I18<4,"REPONER YA","OK"))) -> SIN TASA — no vendió
B19: SUBTOTAL MODULADOS — pedido ejecutable sin condición | F19: =F6+F7+F8+F9+F10+F11 -> 6911 | M19: =M6+M7+M8+M9+M10+M11 -> 3686 | O19: =O6+O7+O8+O9+O10+O11 -> 123398.18 | P19: =P6+P7+P8+P9+P10+P11 -> 16049
B20: SUBTOTAL NO MODULADOS — pedido CONDICIONADO a extender vigencia | F20: =F12+F13+F14+F15+F16+F17+F18 -> 1535 | M20: =M12+M13+M14+M15+M16+M17+M18 -> 2438 | O20: =O12+O13+O14+O15+O16+O17+O18 -> 55353.95 | P20: =P12+P13+P14+P15+P16+P17+P18 -> 5806
B21: TOTAL 13 ÍTEMS ACTIVOS | F21: =SUM(F6:F18) -> 8446 | M21: =SUM(M6:M18) -> 6124 | O21: =SUM(O6:O18) -> 178752.13 | P21: =SUM(P6:P18) -> 21855
B23: Lectura del semáforo: SOBRE-STOCK = el stock ya en tienda cubre más que todo el horizonte; pedir ahí financia inventario muerto. REPONER YA = menos de 4 semanas de cobertura. SIN TASA = no vendió en ninguna tienda, no hay base para calcular.
B24: Los 5 ítems con vencimiento 02/09/2026 no deben pedirse hasta que la vigencia esté extendida vía formulario de ítems temporales, aunque el modelo calcule un sugerido.
B25: Correlación exacta que vale notar: los 6 modulados no tienen fecha de vencimiento; los 7 no modulados la tienen todos. Ser no modulado y ser temporal es lo mismo en este catálogo.

Sheet Prepedido Oktoberfest
A1: PREPEDIDO HB OKTOBERFESTBIER — reactivación de los 2 ítems + 4-way de temporada
A2: Ítem YA EXISTE inactivo (LATA): es reactivación, no alta nueva. Barrilito 5 L DESCARTADO del prepedido el 24/08 (16 u en bodega, sin compra en camino).
A3: ◀ HUB
A4: SUPUESTOS
A5: Tiendas con lata (toda la red) | C5: 40
A6: Cajas por tienda — lata (WHPK 20 u) | C6: 1 | D6: arranque conservador; se repone con venta
A7: Reserva para 4-ways y AAA (u) | C7: 200
A8: Tiendas AAA con barrilito 5 L — descartado | C8: 14 | D8: las de la Ola 1
A9: Barrilitos por tienda AAA | C9: 4
A10: PVP lata (punto de precio Max: múltiplos de Q5) | C10: 20 | D10: venta directa actual comprobada: Q25 (Recurrente, 16/08)
A11: Semanas de ventana (12/09 → 04/10 + cola) | C11: 4
A13: CÁLCULO
A14: Lata — pedido inicial (u) | C14: =C5*C6*20+C7 -> 1000
A15: Lata — cajas de 20 | C15: =(C5*C6*20+C7)/20 -> 50
A16: Lata — venta requerida para agotar (u/tienda/semana) | C16: =(C5*C6*20+C7)/C5/C11 -> 6.25
A17: Referencia: tasa observada HB Helles donde rota (u/tda/sem) | C17: 4.4
A18: Barrilito 5 L — DESCARTADO 24/08 | C18: 0 | D18: Sin stock (16 u) ni compra en camino: no llega al 12/09. Reevaluar para Navidad si se importa.
A19: Ingreso potencial lata a PVP (Q) | C19: =(C5*C6*20+C7)*C10 -> 20000
A21: 4-WAY DE TEMPORADA — 14 tiendas Ola 1
A22: Cara | B22: SKU | C22: Unidades por cara (aprox) | D22: Nota
A23: 1 | B23: HB Oktoberfestbier lata 500 ml | C23: 72 | D23: Protagonista hasta el 4/10; después rota a Halloween
A24: 2 | B24: HB Helles Lager lata 500 ml | C24: 72 | D24: Mejor ejecución del portafolio (48%); REQUIERE extender vigencia (10/11) y asignarle capacidad
A25: 3 | B25: 4-pack Trooper (troquel final listo) | C25: 18 | D25: Priorizar aquí el lote FOTD que vence dic-2026 (66 u documentadas)
A26: 4 | B26: 4-pack Hobgoblin Halloween (troquel final listo) | C26: 18 | D26: Del 1/10 en adelante; antes, Sapporo Black como cuarta cara
B27: TOTAL por 4-way ≈ 180 u · 14 tiendas ≈ 2,520 u en exhibición adicional
A29: Regla de reposición: el 71.8% de la venta cae viernes-sábado-domingo (curva del reporte 113344554). El 4-way se surte JUEVES, sin excepción.
A30: Specs logísticos (VNDR9/Retail Link): lata 500 ml = 20 u/caja, 24 cajas/cama, 6 camas/tarima (2,880 u). El pedido inicial de 1,000 u de Oktoberfestbier = ~50 cajas ≈ 2 camas.
A31: CONDICIÓN PREVIA: reactivar la LATA y asignarle MAX_SHELF > 0. Un ítem reactivado sin capacidad no repone (la lección de los 7 no modulados).
B33: RESPALDO DE BODEGA (Odoo en vivo, 24/08)
B34: Ítem | C34: Bodega Clan | D34: Lectura
B35: HB Oktoberfestbier LATA 500 ml | C35: 3,705 u disponibles | D35: Cubre 3.7× el prepedido de 1,000 → sin riesgo de fill rate
B36: Barrilito Oktoberfest 5 L | C36: 16 u disponibles | D36: Descartado del prepedido 24/08: se vende SOLO lata. Reevaluar si se importa (Navidad).

Sheet Liquidación
A1: LIQUIDACIÓN — 8 ítems inactivos que no se pueden pedir
A2: Son los ítems con existencia en tienda que no aparecen en el listado de catálogo activo (6 modulados + 7 no modulados).
A3: ◀ HUB
A4: Ítem | B4: Descripción | C4: Combos | D4: Stock (u) | E4: Costo unit. | F4: Valor a costo | G4: Venta semana (u) | H4: Venta semana (Q) | I4: Combos sin venta | J4: En NP como "ítem a sustituir"
